Workbook

Sheet Main Dashboard
E9: Particular | F9: 10-Oct-2024 | G9: 9-Oct-20242 | H9: 8-Oct-2024
E10: Total Running Frame | F10: =F22+G22+H22 -> 111 | G10: 110 | H10: 111
E11: Avg. Efficiency % | F11: =(AVERAGE(F23,G23,H23))/100 -> 0.70388333 | G11: 0.71793 | H11: 0.70891333
E12: Avg. Count | F12: =AVERAGE(F24,G24,H24) -> 9.58 | G12: 9.7066667 | H12: 9
E13: Achieved production (kg) | F13: =SUM(F25,G25,H25) -> 28803.82 | G13: 29917.11 | H13: 27939.79
E14: Loss Idle % | F14: =AVERAGE(F26,G26,H26) -> 7.8446667 | G14: 7.7173333 | H14: 7.4033333
E15: Eb/100 Spindle Hour | F15: =F27+G27+H27 -> 31.712 | G15: 32.797 | H15: 33.806
E16: Total Doffing Detected | F16: =F28+G28+H28 -> 1020 | G16: 986 | H16: 939
E17: Avg Minutes Per Doff | F17: =AVERAGE(F29,G29,H29) -> 5.9113333 | G17: 5.2363333 | H17: 4.9335
E18: Stop % | F18: =AVERAGE(F30,G30,H30) -> 10.599667 | G18: 10.112667 | H18: 10.943
E19: Total End breakages | F19: =F31+G31+H31 -> 22329 | G19: 24073 | H19: 22443
E21: Particular | F21: R/A | G21: R/B | H21: R/C
E22: Total Running Frame | F22: ='Shift-A'!B48 -> 37 | G22: ='Shift-B'!B43 -> 37 | H22: ='Shift-C'!B44 -> 37
E23: Avg. Efficiency % | F23: =ROUND(AVERAGE('Shift-A'!D:D),3) -> 70.371 | G23: =ROUND(AVERAGE('Shift-B'!D:D),3) -> 72.729 | H23: =ROUND(AVERAGE('Shift-C'!D:D),3) -> 68.065
E24: Avg. Count | F24: =ROUND(AVERAGE('Shift-A'!Q:Q),3) -> 9.624 | G24: =ROUND(AVERAGE('Shift-B'!Q:Q),3) -> 9.593 | H24: =ROUND(AVERAGE('Shift-C'!Q:Q),3) -> 9.523
E25: Achieved production (kg) | F25: =ROUND(SUM('Shift-A'!O:O),3) -> 9718.61 | G25: =ROUND(SUM('Shift-B'!O:O),3) -> 9872.39 | H25: =ROUND(SUM('Shift-C'!O:O),3) -> 9212.82
E26: Loss Idle % | F26: =ROUND(AVERAGE('Shift-A'!H:H),3) -> 7.457 | G26: =ROUND(AVERAGE('Shift-B'!H:H),3) -> 8.086 | H26: =ROUND(AVERAGE('Shift-C'!H:H),3) -> 7.991
E27: Eb/100 Spindle Hour | F27: =ROUND(AVERAGE('Shift-A'!K:K),3) -> 9.948 | G27: =ROUND(AVERAGE('Shift-B'!K:K),3) -> 10.965 | H27: =ROUND(AVERAGE('Shift-C'!K:K),3) -> 10.799
E28: Total Doffing Detected | F28: =ROUND(SUM('Shift-A'!N:N),3) -> 348 | G28: =ROUND(SUM('Shift-B'!N:N),3) -> 342 | H28: =ROUND(SUM('Shift-C'!N:N),3) -> 330
E29: Avg Minutes Per Doff | F29: =ROUND(AVERAGE('Shift-A'!J:J),3) -> 5.91 | G29: =ROUND(AVERAGE('Shift-B'!J:J),3) -> 5.286 | H29: =ROUND(AVERAGE('Shift-C'!J:J),3) -> 6.538
E30: Stop % | F30: =ROUND(AVERAGE('Shift-A'!F:F),3) -> 10.901 | G30: =ROUND(AVERAGE('Shift-B'!F:F),3) -> 8.621 | H30: =ROUND(AVERAGE('Shift-C'!F:F),3) -> 12.277
E31: Total End breakages | F31: =ROUND(SUM('Shift-A'!L:L),3) -> 7337 | G31: =ROUND(SUM('Shift-B'!L:L),3) -> 7834 | H31: =ROUND(SUM('Shift-C'!L:L),3) -> 7158
C54: =Sheet6!B2 -> 0.89395398

Sheet Shift-A
A1: S/L | B1: M/c No. | C1: Count and Material | D1: AEF % | E1: util % | F1: stop % | G1: spndl Down Time % | H1: % loss idle | I1: Doffing % | J1: min/doff | K1: eb/100sh | L1: eb total | M1: eb idle | N1: doffs | O1: kg | P1: m/min | Q1: Actual Count
A2: 1 | B2: 1 | C2: 6.25 lbs-6.25/ lbs HG | D2: 59.91 | E2: 94.22 | F2: 5.78 | G2: 16.37 | H2: 4.86 | I2: 37.94 | J2: 35.9 | K2: 8.07 | L2: 233 | M2: 46 | N2: 5 | O2: 99.09 | P2: 20.51 | Q2: =VALUE(LEFT(C2, FIND(" lbs", C2)-1)) -> 6.25
A3: 2 | B3: 3 | C3: 9.6 lbs-9.6/2 lbs CRX | D3: 73.14 | E3: 99.41 | F3: 0.59 | G3: 4.4 | H3: 3.94 | I3: 21.87 | J3: 4.5 | K3: 3.13 | L3: 83 | M3: 39 | N3: 23 | O3: 295.98 | P3: 21.75 | Q3: =VALUE(LEFT(C3, FIND(" lbs", C3)-1)) -> 9.6
A4: 3 | B4: 4 | C4: 9.6 lbs-9.6/2 lbs CRX | D4: 75.26 | E4: 85.99 | F4: 14.01 | G4: 4.15 | H4: 3.76 | I4: 6.58 | J4: 3.1 | K4: 3.08 | L4: 74 | M4: 32 | N4: 9 | O4: 281.71 | P4: 22.17 | Q4: =VALUE(LEFT(C4, FIND(" lbs", C4)-1)) -> 9.6
A5: 4 | B5: 5 | C5: 13.0 lbs-13/1 lbs CRT | D5: 66.56 | E5: 94.32 | F5: 5.68 | G5: 16.26 | H5: 15.5 | I5: 11.49 | J5: 3.6 | K5: 6.24 | L5: 217 | M5: 115 | N5: 15 | O5: 424.77 | P5: 25.31 | Q5: =VALUE(LEFT(C5, FIND(" lbs", C5)-1)) -> 13
A6: 5 | B6: 6 | C6: 10.0 lbs-10/1 lbs CRT | D6: 73.18 | E6: 95.47 | F6: 4.53 | G6: 12.54 | H6: 11.96 | I6: 9.75 | J6: 2.9 | K6: 3.61 | L6: 269 | M6: 186 | N6: 16 | O6: 362.1 | P6: 25.77 | Q6: =VALUE(LEFT(C6, FIND(" lbs", C6)-1)) -> 10
A7: 6 | B7: 7 | C7: 13.0 lbs-13/1 lbs CRT | D7: 77.64 | E7: 95.83 | F7: 4.17 | G7: 9.05 | H7: 8.02 | I7: 9.14 | J7: 3.3 | K7: 8.96 | L7: 252 | M7: 122 | N7: 13 | O7: 486.97 | P7: 25.08 | Q7: =VALUE(LEFT(C7, FIND(" lbs", C7)-1)) -> 13
A8: 7 | B8: 8 | C8: 13.0 lbs-13/1 lbs CRT | D8: 76.64 | E8: 90.87 | F8: 9.13 | G8: 8.05 | H8: 7.25 | I8: 6.19 | J8: 2 | K8: 8.37 | L8: 230 | M8: 125 | N8: 15 | O8: 498.73 | P8: 25.88 | Q8: =VALUE(LEFT(C8, FIND(" lbs", C8)-1)) -> 13
A9: 8 | B9: 9 | C9: 8.0 lbs-8/1 Lbs IG | D9: 83.75 | E9: 91.35 | F9: 8.65 | G9: 3.94 | H9: 2.81 | I9: 3.66 | J9: 2.5 | K9: 12.29 | L9: 229 | M9: 82 | N9: 7 | O9: 237.3 | P9: 18.31 | Q9: =VALUE(LEFT(C9, FIND(" lbs", C9)-1)) -> 8
A10: 9 | B10: 10 | C10: 13.0 lbs-13/1 lbs CRT | D10: 73.64 | E10: 90.53 | F10: 9.47 | G10: 7.57 | H10: 6.71 | I10: 9.31 | J10: 3.4 | K10: 8.35 | L10: 226 | M10: 107 | N10: 13 | O10: 400.2 | P10: 21.69 | Q10: =VALUE(LEFT(C10, FIND(" lbs", C10)-1)) -> 13
A11: 10 | B11: 11 | C11: 13.0 lbs-13/1 lbs CRT | D11: 73.05 | E11: 87.21 | F11: 12.79 | G11: 8.66 | H11: 8.01 | I11: 5.5 | J11: 2 | K11: 9 | L11: 189 | M11: 78 | N11: 13 | O11: 413.76 | P11: 22.37 | Q11: =VALUE(LEFT(C11, FIND(" lbs", C11)-1)) -> 13
A12: 11 | B12: 13 | C12: 13.0 lbs-13/1 lbs CRT | D12: 52.34 | E12: 88.85 | F12: 11.15 | G12: 19.55 | H12: 18.95 | I12: 16.96 | J12: 6.2 | K12: 6.27 | L12: 181 | M12: 103 | N12: 13 | O12: 333.87 | P12: 25.13 | Q12: =VALUE(LEFT(C12, FIND(" lbs", C12)-1)) -> 13
A13: 12 | B13: 15 | C13: 14.0 lbs-14/1 H | D13: 68.15 | E13: 87.46 | F13: 12.54 | G13: 7.4 | H13: 6.44 | I13: 11.91 | J13: 4.4 | K13: 8.87 | L13: 191 | M13: 80 | N13: 13 | O13: 441.98 | P13: 23.86 | Q13: =VALUE(LEFT(C13, FIND(" lbs", C13)-1)) -> 14
... A40: 39 | B40: 43 | C40: 7.0 lbs-7/1 W | D40: 63.65 | E40: 99.68 | F40: 0.32 | G40: 17.26 | H40: 15.76 | I40: 18.77 | J40: 8.1 | K40: 16.6 | L40: 355 | M40: 182 | N40: 11 | O40: 117.55 | P40: 13.63 | Q40: =VALUE(LEFT(C40, FIND(" lbs", C40)-1)) -> 7
A41: 40
A42: 41
A43: 42
A44: 43
A45: 44
B48: =SUMPRODUCT(1/COUNTIF(B2:B40,B2:B40)) -> 37

Sheet Shift-B
A1: S/L | B1: M/c No. | C1: Count and Material | D1: AEF % | E1: util % | F1: stop % | G1: spndl Down Time % | H1: % loss idle | I1: Doffing % | J1: min/doff | K1: eb/100sh | L1: eb total | M1: eb idle | N1: doffs | O1: kg | P1: m/min | Q1: Actual Count
A2: 1 | B2: 1 | C2: 6.25 lbs-6.25/ lbs HG | D2: 90.61 | E2: 99.13 | F2: 0.87 | G2: 3.15 | H2: 2.57 | I2: 5.37 | J2: 3.7 | K2: 8.28 | L2: 127 | M2: 26 | N2: 7 | O2: 223.88 | P2: 20.27 | Q2: =VALUE(LEFT(C2, FIND(" lbs", C2)-1)) -> 6.25
A3: 2 | B3: 3 | C3: 9.6 lbs-9.6/2 lbs CRX | D3: 81.25 | E3: 99.77 | F3: 0.23 | G3: 12.74 | H3: 12.08 | I3: 5.78 | J3: 2.3 | K3: 5.75 | L3: 197 | M3: 118 | N3: 12 | O3: 332.75 | P3: 22.1 | Q3: =VALUE(LEFT(C3, FIND(" lbs", C3)-1)) -> 9.6
A4: 3 | B4: 4 | C4: 9.6 lbs-9.6/2 lbs CRX | D4: 56.39 | E4: 81.65 | F4: 18.35 | G4: 21.76 | H4: 21.5 | I4: 3.5 | J4: 2 | K4: 2.44 | L4: 146 | M4: 122 | N4: 8 | O4: 217.36 | P4: 21.97 | Q4: =VALUE(LEFT(C4, FIND(" lbs", C4)-1)) -> 9.6
A5: 4 | B5: 5 | C5: 13.0 lbs-13/1 lbs CRT | D5: 27.42 | E5: 87.86 | F5: 12.14 | G5: 10.65 | H5: 7.86 | I5: 49.79 | J5: 47.3 | K5: 19.08 | L5: 257 | M5: 58 | N5: 5 | O5: 149.01 | P5: 21.91 | Q5: =VALUE(LEFT(C5, FIND(" lbs", C5)-1)) -> 13
A6: 5 | B6: 6 | C6: 10.0 lbs-10/1 lbs CRT | D6: 70.56 | E6: 86.26 | F6: 13.74 | G6: 6.28 | H6: 5.62 | I6: 9.43 | J6: 3.2 | K6: 8.3 | L6: 178 | M6: 59 | N6: 14 | O6: 355.02 | P6: 25.71 | Q6: =VALUE(LEFT(C6, FIND(" lbs", C6)-1)) -> 10
A7: 6 | B7: 7 | C7: 13.0 lbs-13/1 lbs CRT | D7: 76.95 | E7: 98.09 | F7: 1.91 | G7: 10.34 | H7: 9.4 | I7: 10.8 | J7: 3.4 | K7: 9.13 | L7: 275 | M7: 145 | N7: 15 | O7: 488.67 | P7: 25.04 | Q7: =VALUE(LEFT(C7, FIND(" lbs", C7)-1)) -> 13
A8: 7 | B8: 8 | C8: 13.0 lbs-13/1 lbs CRT | D8: 71.81 | E8: 88.15 | F8: 11.85 | G8: 8.08 | H8: 7.53 | I8: 8.26 | J8: 2.6 | K8: 6.67 | L8: 202 | M8: 119 | N8: 15 | O8: 473.96 | P8: 25.93 | Q8: =VALUE(LEFT(C8, FIND(" lbs", C8)-1)) -> 13
A9: 8 | B9: 9 | C9: 8.0 lbs-8/1 Lbs IG | D9: 62.49 | E9: 96.48 | F9: 3.52 | G9: 13.98 | H9: 2.3 | I9: 20.01 | J9: 13.7 | K9: 9.98 | L9: 267 | M9: 54 | N9: 7 | O9: 169.13 | P9: 17.28 | Q9: =VALUE(LEFT(C9, FIND(" lbs", C9)-1)) -> 8
A10: 9 | B10: 10 | C10: 13.0 lbs-13/1 lbs CRT | D10: 73 | E10: 90.91 | F10: 9.09 | G10: 11.49 | H10: 10.82 | I10: 6.41 | J10: 2.4 | K10: 7.55 | L10: 233 | M10: 131 | N10: 13 | O10: 402.86 | P10: 21.7 | Q10: =VALUE(LEFT(C10, FIND(" lbs", C10)-1)) -> 13
A11: 10 | B11: 11 | C11: 13.0 lbs-13/1 lbs CRT | D11: 69.94 | E11: 89.53 | F11: 10.47 | G11: 12.84 | H11: 12.46 | I11: 6.75 | J11: 2.5 | K11: 4.56 | L11: 191 | M11: 121 | N11: 13 | O11: 394.31 | P11: 22.23 | Q11: =VALUE(LEFT(C11, FIND(" lbs", C11)-1)) -> 13
A12: 11 | B12: 13 | C12: 13.0 lbs-13/1 lbs CRT | D12: 69.57 | E12: 91.6 | F12: 8.4 | G12: 11.44 | H12: 10.89 | I12: 10.59 | J12: 3.6 | K12: 4.33 | L12: 178 | M12: 97 | N12: 14 | O12: 416.6 | P12: 24.91 | Q12: =VALUE(LEFT(C12, FIND(" lbs", C12)-1)) -> 13
A13: 12 | B13: 15 | C13: 14.0 lbs-14/1 H | D13: 64.8 | E13: 81.56 | F13: 18.44 | G13: 8.74 | H13: 8.16 | I13: 8.02 | J13: 3 | K13: 9.97 | L13: 197 | M13: 93 | N13: 13 | O13: 417.11 | P13: 23.73 | Q13: =VALUE(LEFT(C13, FIND(" lbs", C13)-1)) -> 14
... A37: 36 | B37: 42 | C37: 9.0 lbs-9/1 CRT | D37: 71.04 | E37: 87.95 | F37: 12.05 | G37: 14.7 | H37: 12.58 | I37: 2.21 | J37: 5.1 | K37: 36.62 | L37: 514 | M37: 207 | N37: 2 | O37: 174.61 | P37: 14.39 | Q37: =VALUE(LEFT(C37, FIND(" lbs", C37)-1)) -> 9
A38: 37 | B38: 43 | C38: 7.0 lbs-7/1 W | D38: 77.31 | E38: 100 | F38: 0 | G38: 9.36 | H38: 7.79 | I38: 13.33 | J38: 8 | K38: 27.15 | L38: 397 | M38: 142 | N38: 8 | O38: 141.51 | P38: 13.36
A39: 38
A40: 39
B43: =SUMPRODUCT(1/COUNTIF(B2:B38,B2:B38)) -> 37

Sheet Shift-C
B1: Shift | C1: C
A2: S/L | B2: M/c No. | C2: Count and Material | D2: AEF % | E2: util % | F2: stop % | G2: spndl Down Time % | H2: % loss idle | I2: Doffing % | J2: min/doff | K2: eb/100sh | L2: eb total | M2: eb idle | N2: doffs | O2: kg | P2: m/min | Q2: Actual Count
A3: 1 | B3: 1 | C3: 6.25 lbs-6.25/ lbs HG | D3: 73.57 | E3: 83.34 | F3: 16.66 | G3: 5.63 | H3: 5.23 | I3: 4.15 | J3: 3.5 | K3: 4.94 | L3: 96 | M3: 52 | N3: 5 | O3: 156.35 | P3: 19.71 | Q3: =VALUE(LEFT(C3, FIND(" lbs", C3)-1)) -> 6.25 | R3: =IFERROR(INDEX($Q$3:$Q$38, MATCH(0, COUNTIF($S$3:$S19, $Q$3:$Q$38), 0)), "")
A4: 2 | B4: 3 | C4: 9.6 lbs-9.6/2 lbs CRX | D4: 75.48 | E4: 99.43 | F4: 0.57 | G4: 5.98 | H4: 5.39 | I4: 17.97 | J4: 4.7 | K4: 7.39 | L4: 143 | M4: 59 | N4: 18 | O4: 302.95 | P4: 21.98 | Q4: =VALUE(LEFT(C4, FIND(" lbs", C4)-1)) -> 9.6
A5: 3 | B5: 4 | C5: 9.6 lbs-9.6/2 lbs CRX | D5: 73.73 | E5: 83.96 | F5: 16.04 | G5: 4.01 | H5: 3.65 | I5: 6.22 | J5: 3.5 | K5: 4.84 | L5: 107 | M5: 54 | N5: 8 | O5: 290.08 | P5: 22.15 | Q5: =VALUE(LEFT(C5, FIND(" lbs", C5)-1)) -> 9.6
A6: 4 | B6: 5 | C6: 13.0 lbs-13/1 lbs CRT | D6: 55.92 | E6: 64.48 | F6: 35.52 | G6: 5.09 | H6: 4.63 | I6: 3.46 | J6: 3 | K6: 7.28 | L6: 129 | M6: 77 | N6: 5 | O6: 261 | P6: 20.49 | Q6: =VALUE(LEFT(C6, FIND(" lbs", C6)-1)) -> 13
A7: 5 | B7: 6 | C7: 10.0 lbs-10/1 lbs CRT | D7: 66.74 | E7: 85.03 | F7: 14.97 | G7: 10.61 | H7: 9.93 | I7: 7.69 | J7: 2.6 | K7: 8.2 | L7: 239 | M7: 121 | N7: 14 | O7: 332.08 | P7: 25.68 | Q7: =VALUE(LEFT(C7, FIND(" lbs", C7)-1)) -> 10
A8: 6 | B8: 7 | C8: 13.0 lbs-13/1 lbs CRT | D8: 73.94 | E8: 92.67 | F8: 7.33 | G8: 8.82 | H8: 8.11 | I8: 9.9 | J8: 3.3 | K8: 7.29 | L8: 215 | M8: 101 | N8: 14 | O8: 458.23 | P8: 25.11 | Q8: =VALUE(LEFT(C8, FIND(" lbs", C8)-1)) -> 13
A9: 7 | B9: 8 | C9: 13.0 lbs-13/1 lbs CRT | D9: 74.4 | E9: 86.55 | F9: 13.45 | G9: 3.5 | H9: 2.91 | I9: 8.64 | J9: 3.2 | K9: 9 | L9: 150 | M9: 56 | N9: 13 | O9: 465 | P9: 25.7 | Q9: =VALUE(LEFT(C9, FIND(" lbs", C9)-1)) -> 13
A10: 8 | B10: 9 | C10: 8.0 lbs-8/1 Lbs IG | D10: 77.39 | E10: 96.77 | F10: 3.23 | G10: 15.92 | H10: 14.8 | I10: 3.46 | J10: 4.1 | K10: 21.14 | L10: 313 | M10: 100 | N10: 4 | O10: 182.4 | P10: 15.18 | Q10: =VALUE(LEFT(C10, FIND(" lbs", C10)-1)) -> 8
A11: 9 | B11: 10 | C11: 13.0 lbs-13/1 lbs CRT | D11: 69.62 | E11: 86.08 | F11: 13.92 | G11: 9.88 | H11: 9.65 | I11: 6.58 | J11: 2.4 | K11: 3.83 | L11: 173 | M11: 110 | N11: 13 | O11: 382.52 | P11: 21.7 | Q11: =VALUE(LEFT(C11, FIND(" lbs", C11)-1)) -> 13
A12: 10 | B12: 11 | C12: 13.0 lbs-13/1 lbs CRT | D12: 73.25 | E12: 92.17 | F12: 7.83 | G12: 10.02 | H12: 9.53 | I12: 8.9 | J12: 3 | K12: 6.54 | L12: 206 | M12: 113 | N12: 14 | O12: 415.74 | P12: 22.34 | Q12: =VALUE(LEFT(C12, FIND(" lbs", C12)-1)) -> 13
A13: 11 | B13: 13 | C13: 13.0 lbs-13/1 lbs CRT | D13: 42.06 | E13: 85.36 | F13: 14.64 | G13: 26.9 | H13: 26.61 | I13: 16.39 | J13: 5.8 | K13: 2.36 | L13: 190 | M13: 150 | N13: 13 | O13: 259.73 | P13: 25.16 | Q13: =VALUE(LEFT(C13, FIND(" lbs", C13)-1)) -> 13
A14: 12 | B14: 15 | C14: 14.0 lbs-14/1 H | D14: 61.85 | E14: 76.72 | F14: 23.28 | G14: 6.84 | H14: 6.36 | I14: 8.02 | J14: 3.5 | K14: 7.3 | L14: 156 | M14: 89 | N14: 11 | O14: 373.28 | P14: 22.01 | Q14: =VALUE(LEFT(C14, FIND(" lbs", C14)-1)) -> 14
A15: 13 | B15: 16 | C15: 14.0 lbs-14/1 H | D15: 63.05 | E15: 100 | F15: 0 | G15: 5.48 | H15: 4.65 | I15: 31.47 | J15: 6 | K15: 12.81 | L15: 190 | M15: 68 | N15: 25 | O15: 417.5 | P15: 24.23 | Q15: =VALUE(LEFT(C15, FIND(" lbs", C15)-1)) -> 14
... A39: 37 | B39: 43 | C39: 7.0 lbs-7/1 W | D39: 65.79 | E39: 100 | F39: 0 | G39: 9.56 | H39: 8.33 | I39: 24.65 | J39: 9.8 | K39: 18.99 | L39: 307 | M39: 133 | N39: 12 | O39: 124.55 | P39: 13.8 | Q39: =VALUE(LEFT(C39, FIND(" lbs", C39)-1)) -> 7
B44: =SUMPRODUCT(1/COUNTIF(B3:B39,B3:B39)) -> 37

Sheet prod
C1: JANATA JUTE MILLS LIMITED
C2: Dobra, Boalmari, Faridpur
B3: Shift | C3: A
B4: Count | C4: Nominal Count | D4: Frame | E4: RPM | F4: TPI | G4: Theoretical Production | H4: Actual Production | I4: Efficiency% | J4: 0.8 | K4: 0.75 | L4: 0.7
B5: 6 | C5: 6/1 IG | E5: 3600 | F5: 5.2 | G5: =(E5*VALUE(LEFT(B5,3)*120*60*8)/(F5*14400*2.2046*36))*D5 -> 0 | I5: =(H5*100)/G5 -> #DIV/0! | J5: =G5*0.8 -> 0 | K5: =G5*0.75 -> 0 | L5: =G5*0.7 -> 0
B6: 6.85 | C6: 6/2 H | D6: 1 | E6: 3800 | F6: 5.2 | G6: =(E6*VALUE(LEFT(B6,3)*120*60*8)/(F6*14400*2.2046*36))*D6 -> 250.44759 | I6: =(H6*100)/G6 -> 0 | J6: =G6*0.8 -> 200.35807 | K6: =G6*0.75 -> 187.83569 | L6: =G6*0.7 -> 175.31331
B7: 7 | C7: 7/1 W | D7: 4 | E7: 3100 | F7: 5.1 | G7: =(E7*VALUE(LEFT(B7,3)*120*60*8)/(F7*14400*2.2046*36))*D7 -> 857.78261 | I7: =(H7*100)/G7 -> 0 | J7: =G7*0.8 -> 686.22609 | K7: =G7*0.75 -> 643.33696 | L7: =G7*0.7 -> 600.44783
B8: 7.25 | C8: 7.25/1 W | E8: 3800 | F8: 5.05 | G8: =(E8*VALUE(LEFT(B8,3)*120*60*8)/(F8*14400*2.2046*36))*D8 -> 0 | I8: =(H8*100)/G8 -> #DIV/0! | J8: =G8*0.8 -> 0 | K8: =G8*0.75 -> 0 | L8: =G8*0.7 -> 0
B9: 7.7 | C9: 7.7/1 IG | D9: 3 | E9: 4000 | F9: 5 | G9: =(E9*VALUE(LEFT(B9,3)*120*60*8)/(F9*14400*2.2046*36))*D9 -> 931.38589 | I9: =(H9*100)/G9 -> 0 | J9: =G9*0.8 -> 745.10871 | K9: =G9*0.75 -> 698.53942 | L9: =G9*0.7 -> 651.97012
B10: 8 | C10: 8/1 IG | D10: 11 | E10: 4000 | F10: 4.77 | G10: =(E10*VALUE(LEFT(B10,3)*120*60*8)/(F10*14400*2.2046*36))*D10 -> 3719.2209 | I10: =(H10*100)/G10 -> 0 | J10: =G10*0.8 -> 2975.3767 | K10: =G10*0.75 -> 2789.4157 | L10: =G10*0.7 -> 2603.4546
B11: 8 | C11: 8/2 CRX | E11: 4000 | F11: 4.77 | G11: =(E11*VALUE(LEFT(B11,3)*120*60*8)/(F11*14400*2.2046*36))*D11 -> 0 | I11: =(H11*100)/G11 -> #DIV/0! | J11: =G11*0.8 -> 0 | K11: =G11*0.75 -> 0 | L11: =G11*0.7 -> 0
B12: 8.25 | C12: 8.25/1 W | D12: 4 | E12: 3200 | F12: 4.7 | G12: =(E12*VALUE(LEFT(B12,3)*120*60*8)/(F12*14400*2.2046*36))*D12 -> 1125.5211 | I12: =(H12*100)/G12 -> 0 | J12: =G12*0.8 -> 900.4169 | K12: =G12*0.75 -> 844.14085 | L12: =G12*0.7 -> 787.86479
B13: 8.5 | C13: 8.5/1 H | D13: 1 | E13: 3600 | F13: 4.73 | G13: =(E13*VALUE(LEFT(B13,3)*120*60*8)/(F13*14400*2.2046*36))*D13 -> 326.05283 | I13: =(H13*100)/G13 -> 0 | J13: =G13*0.8 -> 260.84226 | K13: =G13*0.75 -> 244.53962 | L13: =G13*0.7 -> 228.23698
B14: 9 | C14: 9/1 VOT | D14: 1 | E14: 3600 | F14: 4.7 | G14: =(E14*VALUE(LEFT(B14,3)*120*60*8)/(F14*14400*2.2046*36))*D14 -> 347.43602 | I14: =(H14*100)/G14 -> 0 | J14: =G14*0.8 -> 277.94881 | K14: =G14*0.75 -> 260.57701 | L14: =G14*0.7 -> 243.20521
B15: 9.6 | C15: 9/1 vot | D15: 3 | E15: 3600 | F15: 4.6 | G15: =(E15*VALUE(LEFT(B15,3)*120*60*8)/(F15*14400*2.2046*36))*D15 -> 1135.9647 | I15: =(H15*100)/G15 -> 0 | J15: =G15*0.8 -> 908.77178 | K15: =G15*0.75 -> 851.97354 | L15: =G15*0.7 -> 795.17531
B16: 11 | C16: 11/1 h | E16: 3800 | F16: 3.9 | G16: =(E16*VALUE(LEFT(B16,3)*120*60*8)/(F16*14400*2.2046*36))*D16 -> 0 | I16: =(H16*100)/G16 -> #DIV/0! | J16: =G16*0.8 -> 0 | K16: =G16*0.75 -> 0 | L16: =G16*0.7 -> 0
B17: 12 | C17: 12/1 CRT | E17: 3800 | F17: 3.85 | G17: =(E17*VALUE(LEFT(B17,3)*120*60*8)/(F17*14400*2.2046*36))*D17 -> 0 | I17: =(H17*100)/G17 -> #DIV/0! | J17: =G17*0.8 -> 0 | K17: =G17*0.75 -> 0 | L17: =G17*0.7 -> 0
B18: 13 | C18: 13/1 CRT | D18: 9 | E18: 3700 | F18: 3.75 | G18: =(E18*VALUE(LEFT(B18,3)*120*60*8)/(F18*14400*2.2046*36))*D18 -> 5818.1378 | I18: =(H18*100)/G18 -> 0 | J18: =G18*0.8 -> 4654.5103 | K18: =G18*0.75 -> 4363.6034 | L18: =G18*0.7 -> 4072.6965
B19: 14 | C19: 14/2 H | D19: 3 | E19: 3600 | F19: 3.65 | G19: =(E19*VALUE(LEFT(B19,3)*120*60*8)/(F19*14400*2.2046*36))*D19 -> 2087.789 | I19: =(H19*100)/G19 -> 0 | J19: =G19*0.8 -> 1670.2312 | K19: =G19*0.75 -> 1565.8418 | L19: =G19*0.7 -> 1461.4523
B20: 10 | C20: 10/1 W | E20: 3800 | F20: 4.1 | G20: =(E20*VALUE(LEFT(B20,3)*120*60*8)/(F20*14400*2.2046*36))*D20 -> 0 | I20: =(H20*100)/G20 -> #DIV/0! | J20: =G20*0.8 -> 0 | K20: =G20*0.75 -> 0 | L20: =G20*0.7 -> 0
B21: 10.5 | C21: 10.5/1 IG | E21: 3800 | F21: 3.95 | G21: =(E21*VALUE(LEFT(B21,3)*120*60*8)/(F21*14400*2.2046*36))*D21 -> 0 | I21: =(H21*100)/G21 -> #DIV/0! | J21: =G21*0.8 -> 0 | K21: =G21*0.75 -> 0 | L21: =G21*0.7 -> 0
B22: 14 | C22: 14/1 O | E22: 3700 | F22: 3.65 | G22: =(E22*VALUE(LEFT(B22,3)*120*60*8)/(F22*14400*2.2046*36))*D22 -> 0 | I22: =(H22*100)/G22 -> #DIV/0! | J22: =G22*0.8 -> 0 | K22: =G22*0.75 -> 0 | L22: =G22*0.7 -> 0
I26: =(H26*100)/G26 -> #DIV/0!
B27: =SUMPRODUCT(B5:B22,D5:D22)/SUM(D5:D22) -> 9.60625 | D27: =SUM(D5:D26) -> 40 | E27: =AVERAGE(E5:E26) -> 3694.4444 | F27: =AVERAGE(F5:F26) -> 4.4816667 | G27: =SUM(G5:G26) -> 16599.739 | H27: =SUM(H5:H26) -> 0 | I27: =AVERAGEIF(I5:I26,"<>#DIV/0!") -> 0 | J27: =SUM(J5:J26) -> 13279.791 | K27: =SUM(K5:K26) -> 12449.804 | L27: =SUM(L5:L26) -> 11619.817
C30: Production | D30: Efficiency%
C31: 12025 | D31: =C31/G27 -> 0.724409
C34: JANATA JUTE MILLS LIMITED
C35: Dobra, Boalmari, Faridpur
B36: Shift | C36: B
B37: Count | C37: Nominal Count | D37: Frame | E37: RPM | F37: TPI | G37: Theoretical Production | H37: Actual Production | I37: Efficiency% | J37: 0.8 | K37: 0.75 | L37: 0.7
B38: 6 | C38: 6/1 IG | E38: 3600 | F38: 5.2 | G38: =(E38*VALUE(LEFT(B38,3)*120*60*8)/(F38*14400*2.2046*36))*D38 -> 0 | I38: =(H38*100)/G38 -> #DIV/0! | J38: =G38*0.8 -> 0 | K38: =G38*0.75 -> 0 | L38: =G38*0.7 -> 0
B39: 6.85 | C39: 6/2 H | E39: 3800 | F39: 5.2 | G39: =(E39*VALUE(LEFT(B39,3)*120*60*8)/(F39*14400*2.2046*36))*D39 -> 0 | I39: =(H39*100)/G39 -> #DIV/0! | J39: =G39*0.8 -> 0 | K39: =G39*0.75 -> 0 | L39: =G39*0.7 -> 0
A40: 1 | B40: 7 | C40: 7/1 W | D40: 4 | E40: 3100 | F40: 5.1 | G40: =(E40*VALUE(LEFT(B40,3)*120*60*8)/(F40*14400*2.2046*36))*D40 -> 857.78261 | I40: =(H40*100)/G40 -> 0 | J40: =G40*0.8 -> 686.22609 | K40: =G40*0.75 -> 643.33696 | L40: =G40*0.7 -> 600.44783
B41: 7.25 | C41: 7.25/1 W | E41: 3800 | F41: 5.05 | G41: =(E41*VALUE(LEFT(B41,3)*120*60*8)/(F41*14400*2.2046*36))*D41 -> 0 | I41: =(H41*100)/G41 -> #DIV/0! | J41: =G41*0.8 -> 0 | K41: =G41*0.75 -> 0 | L41: =G41*0.7 -> 0
A42: 1 | B42: 7.7 | C42: 7.7/1 IG | D42: 4 | E42: 4000 | F42: 5 | G42: =(E42*VALUE(LEFT(B42,3)*120*60*8)/(F42*14400*2.2046*36))*D42 -> 1241.8479 | I42: =(H42*100)/G42 -> 0 | J42: =G42*0.8 -> 993.47828 | K42: =G42*0.75 -> 931.38589 | L42: =G42*0.7 -> 869.2935
A43: 1 | B43: 8 | C43: 8/1 IG | D43: 12 | E43: 4000 | F43: 4.77 | G43: =(E43*VALUE(LEFT(B43,3)*120*60*8)/(F43*14400*2.2046*36))*D43 -> 4057.3319 | I43: =(H43*100)/G43 -> 0 | J43: =G43*0.8 -> 3245.8655 | K43: =G43*0.75 -> 3042.9989 | L43: =G43*0.7 -> 2840.1323
B44: 8 | C44: 8/2 CRX | E44: 4000 | F44: 4.77 | G44: =(E44*VALUE(LEFT(B44,3)*120*60*8)/(F44*14400*2.2046*36))*D44 -> 0 | I44: =(H44*100)/G44 -> #DIV/0! | J44: =G44*0.8 -> 0 | K44: =G44*0.75 -> 0 | L44: =G44*0.7 -> 0
A45: 1 | B45: 8.25 | C45: 8.25/1 W | D45: 4 | E45: 3200 | F45: 4.7 | G45: =(E45*VALUE(LEFT(B45,3)*120*60*8)/(F45*14400*2.2046*36))*D45 -> 1125.5211 | I45: =(H45*100)/G45 -> 0 | J45: =G45*0.8 -> 900.4169 | K45: =G45*0.75 -> 844.14085 | L45: =G45*0.7 -> 787.86479
B46: 8.5 | C46: 8.5/1 H | D46: 2 | E46: 3600 | F46: 4.73 | G46: =(E46*VALUE(LEFT(B46,3)*120*60*8)/(F46*14400*2.2046*36))*D46 -> 652.10566 | I46: =(H46*100)/G46 -> 0 | J46: =G46*0.8 -> 521.68453 | K46: =G46*0.75 -> 489.07924 | L46: =G46*0.7 -> 456.47396
B47: 9 | C47: 9/1 VOT | E47: 3600 | F47: 4.7 | G47: =(E47*VALUE(LEFT(B47,3)*120*60*8)/(F47*14400*2.2046*36))*D47 -> 0 | I47: =(H47*100)/G47 -> #DIV/0! | J47: =G47*0.8 -> 0 | K47: =G47*0.75 -> 0 | L47: =G47*0.7 -> 0
...

Sheet input
F2: Date | G2: 45575 | K2: Summery | L2: R/A | M2: R/B | N2: R/C
F3: Shift | G3: R/A | H3: R/B | I3: R/C | K3: Theoretical prod. (kg) | L3: =prod!G27 -> 16599.739 | M3: =prod!G60 -> 16330.021 | N3: =prod!G93 -> 16541.876
F4: Sarder | G4: Shohidul | H4: Sujon | I4: Alamin | K4: Prod. in 80% eff. (kg) | L4: =prod!J27 -> 13279.791 | M4: =prod!J60 -> 13064.017 | N4: =prod!J93 -> 13233.501
F5: Line-man | K5: Actual Prod. (kg) | L5: =prod!C31 -> 12025 | M5: =prod!C64 -> 12125 | N5: =prod!C97 -> 11802
F6: (01-08) | G6: Akash | H6: Emdadul | I6: Alauddin | K6: Efficiency (%) | L6: =prod!D31 -> 0.724409 | M6: =prod!D64 -> 0.74249752 | N6: =prod!D97 -> 0.71346199
F7: (09-16) | G7: Torikul | H7: mamun | I7: Alamin | K7: Stop% | L7: =AVERAGE(H13:H17) -> 10.67775 | M7: =AVERAGE(H18:H22) -> 9.1446494 | N7: =AVERAGE(H23:H27) -> 12.122015
F8: (17-24) | G8: Farhad | H8: Sabbir | I8: Tamim | K8: min/Doff | L8: =AVERAGE(I13:I17) -> 5.8716667 | M8: =AVERAGE(I18:I22) -> 5.3039329 | N8: =AVERAGE(I23:I27) -> 5.9847576
F9: (25-32) | G9: Rabbani | H9: nayon | I9: Sajib | K9: Doff | L9: =SUM(J13:J17) -> 348 | M9: =SUM(J18:J22) -> 342 | N9: =SUM(J23:J27) -> 330
F10: (33-44) | G10: Riazul | H10: shihab | I10: Sujon
B12: date | C12: shift | D12: Sarder | E12: line-man | G12: AEF% | H12: Stop% | I12: Min/doff | J12: doff
A13: =F13 -> (01-08) | B13: =$G$2 -> 45575 | C13: =$G$3 -> R/A | D13: =$G$4 -> Shohidul | E13: =G6 -> Akash | F13: (01-08) | G13: 68.904286 | H13: 6.27 | I13: 7.9 | J13: 96
A14: =F14 -> (09-16) | B14: =$G$2 -> 45575 | C14: =$G$3 -> R/A | D14: =$G$4 -> Shohidul | E14: =G7 -> Torikul | F14: (09-16) | G14: 69.316667 | H14: 9.1 | I14: 4.3 | J14: 78
A15: =F15 -> (17-24) | B15: =$G$2 -> 45575 | C15: =$G$3 -> R/A | D15: =$G$4 -> Shohidul | E15: =G8 -> Farhad | F15: (17-24) | G15: 68.3425 | H15: 21.07375 | I15: 6.2 | J15: 46
A16: =F16 -> (25-32) | B16: =$G$2 -> 45575 | C16: =$G$3 -> R/A | D16: =$G$4 -> Shohidul | E16: =G9 -> Rabbani | F16: (25-32) | G16: 76.49 | H16: 7.55 | I16: 5.2833333 | J16: 37
A17: =F17 -> (33-44) | B17: =$G$2 -> 45575 | C17: =$G$3 -> R/A | D17: =$G$4 -> Shohidul | E17: =G10 -> Riazul | F17: (33-44) | G17: 68.380833 | H17: 9.395 | I17: 5.675 | J17: 91
A18: =F18 -> (01-08) | B18: =$G$2 -> 45575 | C18: =$H$3 -> R/B | D18: =$H$4 -> Sujon | E18: =H6 -> Emdadul | F18: (01-08) | G18: 67.855714 | H18: 8.4414286 | I18: 9.2142857 | J18: 76
A19: =F19 -> (09-16) | B19: =$G$2 -> 45575 | C19: =$H$3 -> R/B | D19: =$H$4 -> Sujon | E19: =H7 -> mamun | F19: (09-16) | G19: 65.626667 | H19: 8.32 | I19: 5.5833333 | J19: 82
A20: =F20 -> (17-24) | B20: =$G$2 -> 45575 | C20: =$H$3 -> R/B | D20: =$H$4 -> Sujon | E20: =H8 -> Sabbir | F20: (17-24) | G20: 80.0075 | H20: 8.43 | I20: 3.4875 | J20: 60
A21: =F21 -> (25-32) | B21: =$G$2 -> 45575 | C21: =$H$3 -> R/B | D21: =$H$4 -> Sujon | E21: =H9 -> nayon | F21: (25-32) | G21: 69.046 | H21: 13.89 | I21: 3.48 | J21: 39
A22: =F22 -> (33-44) | B22: =$G$2 -> 45575 | C22: =$H$3 -> R/B | D22: =$H$4 -> Sujon | E22: =H10 -> shihab | F22: (33-44) | G22: 76.086364 | H22: 6.6418182 | I22: 4.7545455 | J22: 85
A23: =F23 -> (01-08) | B23: =$G$2 -> 45575 | C23: =$I$3 -> R/C | D23: =$I$4 -> Alamin | E23: =I6 -> Alauddin | F23: (01-08) | G23: 70.54 | H23: 14.934286 | I23: 3.4 | J23: 77
A24: =F24 -> (09-16) | B24: =$G$2 -> 45575 | C24: =$I$3 -> R/C | D24: =$I$4 -> Alamin | E24: =I7 -> Alamin | F24: (09-16) | G24: 64.536667 | H24: 10.483333 | I24: 4.1333333 | J24: 80
A25: =F25 -> (17-24) | B25: =$G$2 -> 45575 | C25: =$I$3 -> R/C | D25: =$I$4 -> Alamin | E25: =I8 -> Tamim | F25: (17-24) | G25: 73.1975 | H25: 10.015 | I25: 7.625 | J25: 49
A26: =F26 -> (25-32) | B26: =$G$2 -> 45575 | C26: =$I$3 -> R/C | D26: =$I$4 -> Alamin | E26: =I9 -> Sajib | F26: (25-32) | G26: 70.082 | H26: 11.712 | I26: 5.02 | J26: 38
A27: =F27 -> (33-44) | B27: =$G$2 -> 45575 | C27: =$I$3 -> R/C | D27: =$I$4 -> Alamin | E27: =I10 -> Sujon | F27: (33-44) | G27: 62.857273 | H27: 13.465455 | I27: 9.7454545 | J27: 86

Sheet result
A3: Mill no: | B3: 2/B | D3: Shift: | E3: =input!G3 -> R/A | F3: Date: | G3: =input!G2 -> 45575
A6: Sardar: | B6: =input!G4 -> Shohidul
A8: 1 | B8: Line-man: | C8: =input!G6 -> Akash | E8: M/C no.- | F8: =input!F6 -> (01-08)
C10: AEF% | D10: Stop% | E10: Min/doff | F10: Doff
C11: =input!G13 -> 68.904286 | D11: =input!H13 -> 6.27 | E11: =input!I13 -> 7.9 | F11: =input!J13 -> 96
A14: 2 | B14: Line-man: | C14: =input!G7 -> Torikul | E14: M/C no.- | F14: =input!F7 -> (09-16)
C16: AEF% | D16: Stop% | E16: Min/doff | F16: Doff
C17: =input!G14 -> 69.316667 | D17: =input!H14 -> 9.1 | E17: =input!I14 -> 4.3 | F17: =input!J14 -> 78
A19: 3 | B19: Line-man: | C19: =input!G8 -> Farhad | E19: M/C no.- | F19: =input!F8 -> (17-24)
C21: AEF% | D21: Stop% | E21: Min/doff | F21: Doff
C22: =input!G15 -> 68.3425 | D22: =input!H15 -> 21.07375 | E22: =input!I15 -> 6.2 | F22: =input!J15 -> 46
A25: 4 | B25: Line-man: | C25: =input!G9 -> Rabbani | E25: M/C no.- | F25: =input!F9 -> (25-32)
C27: AEF% | D27: Stop% | E27: Min/doff | F27: Doff
C28: =input!G16 -> 76.49 | D28: =input!H16 -> 7.55 | E28: =input!I16 -> 5.2833333 | F28: =input!J16 -> 37
A31: 5 | B31: Line-man: | C31: =input!G10 -> Riazul | E31: M/C no.- | F31: =input!F10 -> (33-44)
C33: AEF% | D33: Stop% | E33: Min/doff | F33: Doff
C34: =input!G17 -> 68.380833 | D34: =input!H17 -> 9.395 | E34: =input!I17 -> 5.675 | F34: =input!J17 -> 91
B37: Summery:
B39: Theoretical Production (kg) | C39: 80% eff. Production (kg) | D39: Actual Production (kg) | E39: Efficiency (%) | F39: Stop % | G39: Min/doff | H39: Doff
B40: =input!L3 -> 16599.739 | C40: =input!L4 -> 13279.791 | D40: =input!L5 -> 12025 | E40: =input!L6 -> 0.724409 | F40: =input!L7 -> 10.67775 | G40: =input!L8 -> 5.8716667 | H40: =input!L9 -> 348
A46: Mill no: | B46: 2/B | D46: Shift: | E46: =input!H3 -> R/B | F46: Date: | G46: =input!G2 -> 45575
A49: Sardar: | B49: =input!H4 -> Sujon
A51: 1 | B51: Line-man: | C51: =input!H6 -> Emdadul | E51: M/C no.- | F51: (01-08)
C53: AEF% | D53: Stop% | E53: Min/doff | F53: Doff
C54: =input!G18 -> 67.855714 | D54: =input!H18 -> 8.4414286 | E54: =input!I18 -> 9.2142857 | F54: =input!J18 -> 76
A57: 2 | B57: Line-man: | C57: =input!H7 -> mamun | E57: M/C no.- | F57: (09-16)
C59: AEF% | D59: Stop% | E59: Min/doff | F59: Doff
C60: =input!G19 -> 65.626667 | D60: =input!H19 -> 8.32 | E60: =input!I19 -> 5.5833333 | F60: =input!J19 -> 82
A62: 3 | B62: Line-man: | C62: =input!H8 -> Sabbir | E62: M/C no.- | F62: (17-24)
C64: AEF% | D64: Stop% | E64: Min/doff | F64: Doff
C65: =input!G20 -> 80.0075 | D65: =input!H20 -> 8.43 | E65: =input!I20 -> 3.4875 | F65: =input!J20 -> 60
A68: 4 | B68: Line-man: | C68: =input!H9 -> nayon | E68: M/C no.- | F68: (25-32)
C70: AEF% | D70: Stop% | E70: Min/doff | F70: Doff
C71: =input!G21 -> 69.046 | D71: =input!H21 -> 13.89 | E71: =input!I21 -> 3.48 | F71: =input!J21 -> 39
A74: 5 | B74: Line-man: | C74: =input!H10 -> shihab | E74: M/C no.- | F74: (33-44)
C76: AEF% | D76: Stop% | E76: Min/doff | F76: Doff
C77: =input!G22 -> 76.086364 | D77: =input!H22 -> 6.6418182 | E77: =input!I22 -> 4.7545455 | F77: =input!J22 -> 85
B80: Summery:
B82: Theoretical Production (kg) | C82: 80% eff. Production (kg) | D82: Actual Production (kg) | E82: Efficiency (%) | F82: Stop % | G82: Min/doff | H82: Doff
B83: =input!M3 -> 16330.021 | C83: =input!M4 -> 13064.017 | D83: =input!M5 -> 12125 | E83: =input!M6 -> 0.74249752 | F83: =input!M7 -> 9.1446494 | G83: =input!M8 -> 5.3039329 | H83: =input!M9 -> 342
...

Sheet Sheet6
A1: Criteria | B1: Percentage
A2: Utilization | B2: =(AVERAGE(SUM(AVERAGE('Shift-A'!E2:E48,'Shift-B'!E2:E49,'Shift-C'!E2:E48))))/100 -> 0.89395398
A3: Remainder | B3: =1-B2 -> 0.10604602
A10: Criteria | B10: Percentage
A11: Spindle Downtime
A12: Remainder
A23: Date | B23: Efficiency
A24: 21/09 | B24: 0.7467
A25: 30/09 | B25: 0.7
A26: 01/10 | B26: 0.7
A27: 02/10 | B27: 0.72
A28: 03/10 | B28: 0.7
A29: 04/10 | B29: 0.64
A30: 05/10 | B30: 0.7
A31: 06/10 | B31: 0.68
A32: 07/10 | B32: 0.67
A33: 08/10 | B33: 0.71
A34: 09/10 | B34: 0.72
A35: 10/10 | B35: 0.7

Sheet Horizontal
A1: Particular | B1: Total Running Frame | C1: Avg. Efficiency % | D1: Avg. Count | E1: Achieved production (kg) | F1: Loss Idle % | G1: Eb/100 Spindle Hour | H1: Total Doffing Detected | I1: Avg Minutes Per Doff | J1: Stop % | K1: Total End breakages
A2: R/A | B2: ='Main Dashboard'!F22 -> 37 | C2: ='Main Dashboard'!F23 -> 70.371 | D2: ='Main Dashboard'!F24 -> 9.624 | E2: ='Main Dashboard'!F25 -> 9718.61 | F2: ='Main Dashboard'!F26 -> 7.457 | G2: ='Main Dashboard'!F27 -> 9.948 | H2: ='Main Dashboard'!F28 -> 348 | I2: ='Main Dashboard'!F29 -> 5.91 | J2: ='Main Dashboard'!F30 -> 10.901 | K2: ='Main Dashboard'!F31 -> 7337
A3: R/B | B3: ='Main Dashboard'!G22 -> 37 | C3: ='Main Dashboard'!G23 -> 72.729 | D3: ='Main Dashboard'!G24 -> 9.593 | E3: ='Main Dashboard'!G25 -> 9872.39 | F3: ='Main Dashboard'!G26 -> 8.086 | G3: ='Main Dashboard'!G27 -> 10.965 | H3: ='Main Dashboard'!G28 -> 342 | I3: ='Main Dashboard'!G29 -> 5.286 | J3: ='Main Dashboard'!G30 -> 8.621 | K3: ='Main Dashboard'!G31 -> 7834
A4: R/C | B4: ='Main Dashboard'!H22 -> 37 | C4: ='Main Dashboard'!H23 -> 68.065 | D4: ='Main Dashboard'!H24 -> 9.523 | E4: ='Main Dashboard'!H25 -> 9212.82 | F4: ='Main Dashboard'!H26 -> 7.991 | G4: ='Main Dashboard'!H27 -> 10.799 | H4: ='Main Dashboard'!H28 -> 330 | I4: ='Main Dashboard'!H29 -> 6.538 | J4: ='Main Dashboard'!H30 -> 12.277 | K4: ='Main Dashboard'!H31 -> 7158

Sheet Sheet5
A3: Row Labels | B3: Average of AEF % | C3: Average of stop % | D3: Sum of doffs | E3: Count of Actual Count
A4: 10.0 lbs-10/1 lbs CRT | B4: 71.905714 | C4: 12.742857 | D4: 69 | E4: 7
A5: 14.0 lbs-14/1 H | B5: 73.84 | C5: 8.38 | D5: 8 | E5: 1
A6: 6.0 lbs-6/1 lbs CRX | B6: 81.47 | C6: 2.36 | D6: 5 | E6: 1
A7: 7.0 lbs-7.7/1 lbs CRT | B7: 72.205 | C7: 6.6 | D7: 12 | E7: 2
A8: 7.25 lbs-7.25 /1 lbs CRT | B8: 68.95 | C8: 9.25 | D8: 5 | E8: 1
A9: 7.7 lbs-7.7/1 CRT | B9: 73.805 | C9: 9.155 | D9: 14 | E9: 2
A10: 8.0 lbs-8/1 Lbs IG | B10: 63.473 | C10: 17.293 | D10: 63 | E10: 10
A11: 8.25 lbs-8.25/1 lbs HES | B11: 74.355 | C11: 8.36 | D11: 15 | E11: 2
A12: 13.0 lbs-13/1 lbs CRT | B12: 69.683333 | C12: 13.323333 | D12: 77 | E12: 6
A13: 9.0 lbs-9/1 CRT | B13: 52.55 | C13: 36.72 | D13: 3 | E13: 1
A14: 6.25 lbs-6.25/ lbs HG | B14: 69.84 | C14: 15.56 | D14: 5 | E14: 1
A15: 7.0 lbs-7/1 W | B15: 70.416667 | C15: 9.72 | D15: 22 | E15: 3
A16: Grand Total | B16: 69.048649 | C16: 13.29 | D16: 298 | E16: 37
